
# Created by Ruins mod version 16.2 Ingame Parser
# authoring Player: Catullus

weight=1
embed_into_distance=2
acceptable_target_blocks=
unacceptable_target_blocks=flowing_water,water,flowing_lava,lava
dimensions=12,7,7
allowable_overhang=0
max_leveling=2
leveling_buffer=0
preserve_water=0
preserve_lava=0

rule1=0,100,preserveBlock
rule2=0,100,biomesoplenty:log_4-5
rule3=0,100,biomesoplenty:leaves_1-1
rule4=0,100,biomesoplenty:log_4-1
rule5=0,100,biomesoplenty:log_4-9
rule6=0,100,botania:root-0

layer
1,1,1,1,1,1,1
1,1,1,1,1,1,1
1,1,1,1,1,1,1
1,1,1,1,1,1,1
1,1,6,1,1,6,1
1,1,1,1,1,6,1
1,1,1,1,1,1,1
endlayer

layer
1,1,1,1,1,1,1
1,1,1,1,1,1,1
1,1,1,1,1,1,1
1,1,1,1,1,1,1
1,1,6,1,1,6,1
1,1,1,1,1,1,1
1,1,1,1,1,1,1
endlayer

layer
0,0,0,0,0,0,0
0,0,0,0,0,0,0
0,0,0,0,0,0,0
0,0,0,0,0,0,0
0,0,2,0,0,2,0
0,0,0,0,0,0,0
0,0,0,0,0,0,0
endlayer

layer
0,0,0,0,0,0,0
0,0,0,0,0,0,0
0,0,0,0,0,0,0
0,0,0,0,0,0,0
0,0,2,0,0,2,0
0,0,0,0,0,0,0
0,0,0,0,0,0,0
endlayer

layer
0,0,0,0,0,0,0
0,0,0,0,0,0,0
0,0,0,0,0,0,0
0,0,0,0,3,0,0
0,0,2,3,3,2,0
0,0,0,0,3,0,4
0,0,0,0,0,0,0
endlayer

layer
0,0,0,0,0,0,0
0,0,0,0,0,0,0
0,0,0,0,0,0,0
0,0,0,0,3,0,0
0,0,2,5,5,2,5
0,0,0,0,3,0,0
0,0,0,0,0,0,0
endlayer

layer
0,0,0,0,0,0,0
0,0,3,0,0,0,0
0,4,4,3,0,0,0
0,0,4,0,0,0,0
0,0,2,0,0,2,0
0,0,0,0,0,0,0
0,0,0,0,0,0,0
endlayer

layer
0,3,0,0,0,0,0
3,4,3,0,0,0,0
0,3,0,0,0,0,0
0,0,0,0,0,0,0
0,0,2,0,0,2,0
0,0,0,0,0,0,0
0,0,0,0,0,0,0
endlayer

layer
0,0,0,0,0,0,0
0,0,0,0,0,0,0
0,0,0,0,0,0,0
0,3,0,0,0,0,0
3,5,2,0,0,0,0
0,3,0,0,0,0,0
0,0,0,0,0,0,0
endlayer

layer
0,0,0,0,0,0,0
0,0,0,0,0,0,0
0,0,0,3,0,0,0
0,0,3,4,3,0,0
0,0,2,3,0,0,0
0,0,4,0,0,0,0
0,0,0,0,0,0,0
endlayer

layer
0,0,0,0,0,0,0
0,0,0,0,0,0,0
0,0,0,0,0,0,0
0,0,0,0,0,0,0
0,0,2,0,0,0,0
0,3,4,3,0,0,0
0,0,3,0,0,0,0
endlayer

layer
0,0,0,0,0,0,0
0,0,0,0,0,0,0
0,0,0,0,0,0,0
0,0,3,0,0,0,0
0,3,2,3,0,0,0
0,0,3,0,0,0,0
0,0,0,0,0,0,0
endlayer
