
# Created by Ruins mod version 16.2 Ingame Parser
# authoring Player: TransrealClouden

weight=1
embed_into_distance=2
acceptable_target_blocks=
unacceptable_target_blocks=flowing_water,water,flowing_lava,lava
dimensions=9,7,7
allowable_overhang=0
max_leveling=2
leveling_buffer=0
preserve_water=0
preserve_lava=0

rule1=0,100,botania:root-0
rule2=0,100,biomesoplenty:log_4-5
rule3=0,100,biomesoplenty:leaves_1-1
rule4=0,100,biomesoplenty:log_4-1
rule5=0,100,biomesoplenty:log_4-9
rule6=0,100,preserveBlock

layer
6,6,6,6,6,6,6
6,6,6,6,6,6,6
6,6,6,6,6,6,6
6,6,6,6,1,6,6
6,6,6,6,1,6,6
6,6,6,6,6,6,6
6,6,6,6,6,6,6
endlayer

layer
6,6,6,6,6,6,6
6,6,6,6,6,6,6
6,6,6,6,6,6,6
6,6,6,6,6,6,6
6,6,6,6,1,6,6
6,6,6,6,6,6,6
6,6,6,6,6,6,6
endlayer

layer
0,0,0,0,0,0,0
0,0,0,0,0,0,0
0,0,0,0,0,0,0
0,0,0,0,0,0,0
0,0,0,0,2,0,0
0,0,0,0,0,0,0
0,0,0,0,0,0,0
endlayer

layer
0,0,0,0,0,0,0
0,0,0,0,0,0,0
0,0,0,0,0,0,0
0,0,0,0,0,0,0
0,0,0,0,2,0,0
0,0,0,0,0,0,0
0,0,0,0,0,0,0
endlayer

layer
0,0,0,0,0,0,0
0,0,0,0,0,3,0
0,0,0,0,3,3,3
0,0,0,0,0,3,0
0,0,0,0,2,0,0
0,0,0,0,0,0,0
0,0,0,0,0,0,0
endlayer

layer
0,0,0,0,0,0,0
0,0,0,0,3,0,0
0,0,0,3,4,3,0
0,0,0,0,4,0,0
0,0,0,0,2,0,0
0,0,0,0,0,0,0
0,0,0,0,0,0,0
endlayer

layer
0,0,0,0,0,0,0
0,0,0,0,0,0,0
0,0,0,0,0,0,0
0,0,0,0,0,3,0
0,0,0,0,2,5,3
0,0,0,0,0,3,0
0,0,0,0,0,0,0
endlayer

layer
0,0,0,0,0,0,0
0,0,0,0,0,0,0
0,0,0,0,0,0,0
0,0,0,0,0,3,0
0,0,0,0,2,5,3
0,0,0,0,0,3,0
0,0,0,0,0,0,0
endlayer

layer
0,0,0,0,0,0,0
0,0,0,0,0,0,0
0,0,0,0,0,0,0
0,0,0,0,3,0,0
0,0,0,3,2,3,0
0,0,0,0,3,0,0
0,0,0,0,0,0,0
endlayer
